Workbook

Sheet 4
A1: Prospect Name | B1: Number | C1: Attempts Missing | D1: Status | E1: stage | F1: Call Slot 1 | G1: Attempt 1 | H1: Call Slot 2 | I1: Attempt 2 | J1: Call Slot 3 | K1: Attempt-3 | L1: Call Slot 4 | M1: Attempt-4 | N1: Notes | O1: Next Step
B2: 92 349 6567518 | D2: Not Attended | E2: Call not Recieved | F2: 10:00 - 12:00 PM | G2: Not Recieved | H2: 12:00-02:30 | I2: Not Recieved | J2: 02:30-04:30 | K2: Not Recieved | L2: 04:30-06:00 | N2: not picking up the call / I message
B3: 92 320 5311945 | D3: Not Attended | E3: enroll in next batch | F3: 10:00 - 12:00 PM | G3: Please Call later | H3: 12:00-02:30 | I3: Please Call later | J3: 02:30-04:30 | K3: Please Call later | L3: 04:30-06:00 | M3: Please Call later | N3: next batch
B4: 92 321 4635594 | D4: Not Attended | E4: Call not Recieved | F4: 10:00 - 12:00 PM | G4: Not Recieved | H4: 12:00-02:30 | I4: Not Recieved | J4: 02:30-04:30 | K4: Not Recieved | L4: 04:30-06:00 | N4: not picking up the call / I message
B5: 92 326 9883188 | D5: Not Attended | E5: Awaiting Response | F5: 10:00 - 12:00 PM | G5: Call Recieved | H5: 12:00-02:30 | I5: Not Recieved | J5: 02:30-04:30 | K5: Not Recieved | L5: 04:30-06:00 | N5: Not answer / I message him
B6: 92 332 4382744 | D6: Call Attended | E6: Awaiting payment | F6: 10:00 - 12:00 PM | G6: Call Recieved | H6: 12:00-02:30 | I6: Not Recieved | J6: 02:30-04:30 | K6: Call Recieved | L6: 04:30-06:00 | N6: 26TH
B7: 92 314 3150050 | D7: Not Attended | E7: Call not Recieved | F7: 10:00 - 12:00 PM | G7: Not Recieved | H7: 12:00-02:30 | I7: Not Recieved | J7: 02:30-04:30 | K7: Not Recieved | L7: 04:30-06:00 | N7: number off
B8: 92 345 9634325 | D8: Call Attended | E8: Contacted | F8: 10:00 - 12:00 PM | G8: Call Recieved | H8: 12:00-02:30 | I8: Not Recieved | J8: 02:30-04:30 | K8: Call Recieved | L8: 04:30-06:00 | N8: 29th may
B9: 92 308 6361988 | D9: Call Attended | E9: Contacted | F9: 10:00 - 12:00 PM | G9: Call Recieved | H9: 12:00-02:30 | I9: Not Recieved | J9: 02:30-04:30 | K9: Call Recieved | L9: 04:30-06:00 | N9: he'll update BY TODAY
B10: 92 332 3103893 | D10: Not Attended | E10: Call not Recieved | F10: 10:00 - 12:00 PM | G10: Not Recieved | H10: 12:00-02:30 | I10: Not Recieved | J10: 02:30-04:30 | K10: Not Recieved | L10: 04:30-06:00 | N10: Not picking up the call
B11: 92 317 1397129 | D11: Not Attended | E11: Call not Recieved | F11: 10:00 - 12:00 PM | G11: Not Recieved | H11: 12:00-02:30 | I11: Not Recieved | J11: 02:30-04:30 | K11: Not Recieved | L11: 04:30-06:00 | N11: no message
B12: 92 328 3427019 | D12: Call Attended | E12: Closed - Lost | F12: 10:00 - 12:00 PM | G12: Client lost | H12: 12:00-02:30 | I12: Client lost | J12: 02:30-04:30 | K12: Client lost | L12: 04:30-06:00 | M12: Client lost | N12: lost
B13: 92 309 2050008 | D13: Not Attended | E13: Call not Recieved | F13: 10:00 - 12:00 PM | G13: Not Recieved | H13: 12:00-02:30 | I13: Not Recieved | J13: 02:30-04:30 | K13: Not Recieved | L13: 04:30-06:00 | N13: Not answer / I message him
B14: 92 310 0470538 | D14: Not Attended | E14: Call not Recieved | F14: 10:00 - 12:00 PM | G14: Not Recieved | H14: 12:00-02:30 | I14: Not Recieved | J14: 02:30-04:30 | K14: Not Recieved | L14: 04:30-06:00 | N14: Not answer / I message him
B15: 92 324 1328331 | D15: Not Attended | E15: Call not Recieved | F15: 10:00 - 12:00 PM | G15: Not Recieved | H15: 12:00-02:30 | I15: Not Recieved | J15: 02:30-04:30 | K15: Not Recieved | L15: 04:30-06:00 | N15: Not answer / I message him
B16: 92 309 9622347 | D16: Not Attended | E16: Call not Recieved | F16: 10:00 - 12:00 PM | G16: Not Recieved | H16: 12:00-02:30 | I16: Not Recieved | J16: 02:30-04:30 | K16: Not Recieved | L16: 04:30-06:00 | N16: Not answer / I message him
B17: 92 304 1809388 | D17: Call Attended | E17: Closed - Lost | F17: 10:00 - 12:00 PM | G17: Client lost | H17: 12:00-02:30 | I17: Client lost | J17: 02:30-04:30 | K17: Client lost | L17: 04:30-06:00 | M17: Client lost | N17: he is going in Army academicfor 6 month
B18: 92 302 7117295 | D18: Call Attended | E18: Closed - Lost | F18: 10:00 - 12:00 PM | G18: Client lost | H18: 12:00-02:30 | I18: Client lost | J18: 02:30-04:30 | K18: Client lost | L18: 04:30-06:00 | M18: Client lost | N18: lost
B19: 92 308 2050360 | D19: Call Attended | E19: Closed - Lost | F19: 10:00 - 12:00 PM | G19: Client lost | H19: 12:00-02:30 | I19: Client lost | J19: 02:30-04:30 | K19: Client lost | L19: 04:30-06:00 | M19: Client lost | N19: want course in free
B20: 92 314 9977301 | D20: Call Attended | E20: Awaiting Response | F20: 10:00 - 12:00 PM | G20: Not Recieved | H20: 12:00-02:30 | I20: Not Recieved | J20: 02:30-04:30 | K20: Call Recieved | L20: 04:30-06:00 | N20: not picking up the call
B21: 92 316 9322437 | D21: Call Attended | E21: Contacted | F21: 10:00 - 12:00 PM | G21: Call Recieved | H21: 12:00-02:30 | I21: Not Recieved | J21: 02:30-04:30 | K21: Call Recieved | L21: 04:30-06:00 | N21: 28th
B22: 92 345 0500366 | D22: Call Attended | E22: Call not Recieved | F22: 10:00 - 12:00 PM | G22: Call Recieved | H22: 12:00-02:30 | I22: Call Recieved | J22: 02:30-04:30 | K22: Not Recieved | L22: 04:30-06:00 | N22: she cut the call
B23: 92 335 2151199 | D23: Not Attended | E23: Call not Recieved | F23: 10:00 - 12:00 PM | G23: Not Recieved | H23: 12:00-02:30 | I23: Not Recieved | J23: 02:30-04:30 | K23: Not Recieved | L23: 04:30-06:00 | N23: not picking up the call
B24: 92 313 8247251 | D24: Not Attended | E24: Call not Recieved | F24: 10:00 - 12:00 PM | G24: Not Recieved | H24: 12:00-02:30 | J24: 02:30-04:30 | K24: Not Recieved | L24: 04:30-06:00 | N24: not picking up the call
B25: 92 322 6573551 | D25: Not Attended | E25: Contacted | F25: 10:00 - 12:00 PM | G25: Not Recieved | H25: 12:00-02:30 | J25: 02:30-04:30 | K25: Not Recieved | L25: 04:30-06:00 | N25: not picking up the call
B26: 92 333 8053700 | D26: Not Attended | E26: Call not Recieved | F26: 10:00 - 12:00 PM | G26: Call Recieved | H26: 12:00-02:30 | J26: 02:30-04:30 | K26: Not Recieved | L26: 04:30-06:00 | N26: not picking up the call
A27: Junaid | B27: 92 355 6369605 | D27: Not Attended | E27: enroll in next batch | F27: 10:00 - 12:00 PM | G27: Please Call later | H27: 12:00-02:30 | I27: Please Call later | J27: 02:30-04:30 | K27: Please Call later | L27: 04:30-06:00 | M27: Please Call later | N27: next batch
B28: 92 308 0411714 | D28: Call Attended | E28: Closed - Lost | F28: 10:00 - 12:00 PM | G28: Client lost | H28: 12:00-02:30 | I28: Client lost | J28: 02:30-04:30 | K28: Client lost | L28: 04:30-06:00 | M28: Client lost | N28: lost
B29: 92 313 2132428 | D29: Not Attended | E29: Call not Recieved | F29: 10:00 - 12:00 PM | G29: Not Recieved | H29: 12:00-02:30 | J29: 02:30-04:30 | K29: Not Recieved | L29: 04:30-06:00 | N29: not picking up the call
B30: 92 325 0805768 | D30: Not Attended | E30: Call not Recieved | F30: 10:00 - 12:00 PM | G30: Not Recieved | H30: 12:00-02:30 | J30: 02:30-04:30 | K30: Not Recieved | L30: 04:30-06:00 | N30: not picking up the call
B31: 92 327 8363492 | D31: Not Attended | E31: Call not Recieved | F31: 10:00 - 12:00 PM | G31: Not Recieved | H31: 12:00-02:30 | J31: 02:30-04:30 | K31: Not Recieved | L31: 04:30-06:00 | N31: not picking up the call
B32: 92 347 9111801 | D32: Not Attended | E32: Call not Recieved | F32: 10:00 - 12:00 PM | G32: Not Recieved | H32: 12:00-02:30 | J32: 02:30-04:30 | K32: Not Recieved | L32: 04:30-06:00 | N32: not picking up the call
B33: 92 319 6819015 | D33: Not Attended | E33: Call not Recieved | F33: 10:00 - 12:00 PM | G33: Not Recieved | H33: 12:00-02:30 | J33: 02:30-04:30 | K33: Not Recieved | L33: 04:30-06:00 | N33: not picking up the call
B34: 92 321 4742155 | D34: Not Attended | E34: Call not Recieved | F34: 10:00 - 12:00 PM | H34: 12:00-02:30 | J34: 02:30-04:30 | K34: Not Recieved | L34: 04:30-06:00 | N34: not picking up the call
B35: 92 330 2840635 | D35: Call Attended | E35: Awaiting payment | F35: 10:00 - 12:00 PM | H35: 12:00-02:30 | I35: Call Recieved | J35: 02:30-04:30 | K35: Not Recieved | L35: 04:30-06:00 | N35: 1s june
B36: 92 333 9608073 | D36: Call Attended | E36: Awaiting Response | F36: 10:00 - 12:00 PM | H36: 12:00-02:30 | J36: 02:30-04:30 | K36: Call Recieved | L36: 04:30-06:00 | N36: he'll update
A37: inam ullah | B37: 92 310 8271844 | D37: Call Attended | E37: Awaiting Response | F37: 10:00 - 12:00 PM | H37: 12:00-02:30 | J37: 02:30-04:30 | K37: Call Recieved | L37: 04:30-06:00 | N37: he'll update
B38: 92 333 3684329 | D38: Call Attended | E38: Contacted | F38: 10:00 - 12:00 PM | H38: 12:00-02:30 | J38: 02:30-04:30 | K38: Call Recieved | L38: 04:30-06:00 | N38: no answer
B39: 92 348 2064372 | D39: Call Attended | E39: Awaiting Response | F39: 10:00 - 12:00 PM | H39: 12:00-02:30 | J39: 02:30-04:30 | K39: Call Recieved | L39: 04:30-06:00 | N39: he'll update
B40: 92 342 3607032 | D40: Call Attended | E40: Closed - Lost | F40: 10:00 - 12:00 PM | G40: Client lost | H40: 12:00-02:30 | I40: Client lost | J40: 02:30-04:30 | K40: Client lost | L40: 04:30-06:00 | M40: Client lost | N40: lost
...

Sheet 5
A1: Prospect Name | B1: Number | C1: Attempts Missing | D1: Status | E1: stage | F1: Call Slot 1 | G1: Attempt 1 | H1: Call Slot 2 | I1: Attempt 2 | J1: Call Slot 3 | K1: Attempt-3 | L1: Call Slot 4 | M1: Attempt-4 | N1: Notes | O1: Next Step
A2: Closed - Lost | B2: 0307-3875280 (0343-7833258) | C2: 2 | D2: Call Attended | E2: Closed - Lost | F2: 10:00 - 12:00 PM | G2: Call Recieved | H2: 12:00-02:30 | J2: 02:30-04:30 | K2: Call Recieved | L2: 04:30-06:00 | N2: he said he has some personal issues so for now he drop his plan to enroll in course. | O2: nil
B3: 0343-1336539 | C3: 4 | D3: Not Attended | E3: Call not Recieved | F3: 10:00 - 12:00 PM | H3: 12:00-02:30 | I3: Not Recieved | J3: 02:30-04:30 | K3: Not Recieved | L3: 04:30-06:00 | M3: Not Recieved | N3: still didnt respond on call not on whtsapp | O3: call tomorrow
A4: Mrs Ajmal | B4: 0321-7067642 | C4: 1 | D4: Call Attended | E4: Closed - Lost | F4: 10:00 - 12:00 PM | H4: 12:00-02:30 | J4: 02:30-04:30 | L4: 04:30-06:00 | M4: Call Recieved | N4: she run a welfare asking to join with her.
A5: Waseem | B5: 0306-7362137 (03055640707) | C5: 4 | D5: Not Attended | E5: Contacted | F5: 10:00 - 12:00 PM | G5: Not Recieved | H5: 12:00-02:30 | I5: Not Recieved | J5: 02:30-04:30 | L5: 04:30-06:00 | N5: call him but he didn't respond not on whtsapp. | O5: call him later.
A6: Ubaidullah | B6: 0332-7848087 | C6: 4 | D6: Not Attended | E6: Closed - Lost | F6: 10:00 - 12:00 PM | G6: Not Recieved | H6: 12:00-02:30 | I6: Not Recieved | J6: 02:30-04:30 | L6: 04:30-06:00 | N6: call but didnt attend the call. had talke on whtsapp he is interested but he said he cant take online classes. due to he is living in joint family i asked him to manage and sort out this problem. cant manage to take online classes. | O6: approach him later.
A7: Sufiyan | B7: 0314-5964493 | C7: 2 | D7: Call Attended | E7: Closed - Lost | F7: 10:00 - 12:00 PM | G7: Call Recieved | H7: 12:00-02:30 | I7: Call Recieved | J7: 02:30-04:30 | L7: 04:30-06:00 | N7: said not interested in course. | O7: Nil
B8: 0347-3063900 | C8: 4 | D8: Not Attended | E8: Call not Recieved | F8: 10:00 - 12:00 PM | G8: Not Recieved | H8: 12:00-02:30 | I8: Not Recieved | J8: 02:30-04:30 | K8: Not Recieved | L8: 04:30-06:00 | N8: still num off not respond on whtsapp. | O8: call tomorrow.
A9: Iqra | B9: 0347-2790767 | C9: 2 | D9: Call Attended | E9: Contacted | F9: 10:00 - 12:00 PM | G9: Call Recieved | H9: 12:00-02:30 | I9: Call Recieved | J9: 02:30-04:30 | L9: 04:30-06:00 | N9: had talked with her she said she cant manage time as she is doing job in US based comapany so cant manage time to take online classes. | O9: -
A10: Attaullah | B10: 0312-5872866 | C10: 4 | D10: Not Attended | E10: Call not Recieved | F10: 10:00 - 12:00 PM | G10: Not Recieved | H10: 12:00-02:30 | I10: Not Recieved | J10: 02:30-04:30 | L10: 04:30-06:00 | N10: num off didn't respond on whtsapp | O10: call tomorrow.
A11: Mamoona | B11: 0347-2292892 | C11: 4 | D11: Not Attended | E11: Call not Recieved | F11: 10:00 - 12:00 PM | G11: Not Recieved | H11: 12:00-02:30 | I11: Not Recieved | J11: 02:30-04:30 | L11: 04:30-06:00 | N11: not answer but shared detail on whtsapp . not responding on calll not on whtsapp. | O11: call tomorrow.
A12: Abdul Waheed | B12: 0314-5046175 | C12: 1 | D12: Call Attended | E12: Closed - Lost | F12: 10:00 - 12:00 PM | G12: Call Recieved | H12: 12:00-02:30 | J12: 02:30-04:30 | L12: 04:30-06:00 | N12: had talk he is currently enroll in other course so cant afford at one time 2 courses. | O12: -
A13: Shafaq | B13: 0325-4279620 | C13: 3 | D13: Call Attended | E13: Closed - Lost | F13: 10:00 - 12:00 PM | G13: Not Recieved | H13: 12:00-02:30 | I13: Call Recieved | J13: 02:30-04:30 | L13: 04:30-06:00 | N13: had talked she said she is interested in specific data anylst course. moreover said currently not want to enroll. approch her again but she said she dont want to enroll in this time. | O13: -
A14: Sami | B14: 0300-3563354 | C14: 3 | D14: Not Attended | E14: Closed - Lost | F14: 10:00 - 12:00 PM | G14: Not Recieved | H14: 12:00-02:30 | I14: Call Recieved | J14: 02:30-04:30 | L14: 04:30-06:00 | N14: had talked with him he think that course is free i asked him about how much he can pay he didn't say and hang up. ( number is busy) drop msg on whtsapp. | O14: call after 3 days
A15: Muneeb | B15: 0334-9722883 | C15: 4 | D15: Call Attended | E15: Contacted | F15: 10:00 - 12:00 PM | G15: Call Recieved | H15: 12:00-02:30 | I15: Call Recieved | J15: 02:30-04:30 | L15: 04:30-06:00 | M15: Not Recieved | N15: he is busy in class said call me later. (busy). not answering | O15: call 2 days later
A16: Ahmed | B16: 0320-7807857 | C16: 5 | D16: Call Attended | E16: Contacted | F16: 10:00 - 12:00 PM | G16: Call Recieved | H16: 12:00-02:30 | I16: Call Recieved | J16: 02:30-04:30 | L16: 04:30-06:00 | N16: his bro is interested in course i called him but his bro is not at home. moreover i asked him to call me when his bro is at home. so i can describe it whole course. | O16: call in evening
B17: 0330-8675442 | C17: 4 | D17: Not Attended | E17: Call not Recieved | F17: 10:00 - 12:00 PM | H17: 12:00-02:30 | I17: Not Recieved | J17: 02:30-04:30 | K17: Not Recieved | L17: 04:30-06:00 | N17: still num off not replying on whtsapp. | O17: call 2 days later
A18: Safwan | B18: 0321 5482238 | C18: 3 | D18: Call Attended | E18: Closed - Lost | F18: 10:00 - 12:00 PM | H18: 12:00-02:30 | I18: Not Recieved | J18: 02:30-04:30 | L18: 04:30-06:00 | M18: Call Recieved | N18: Had talked with him he said he is interested in cost accounting .so not interested in this | O18: -
B19: 0348 8815169 | C19: 4 | D19: Call Attended | E19: Closed - Lost | F19: 10:00 - 12:00 PM | G19: Call Recieved | H19: 12:00-02:30 | I19: Not Recieved | J19: 02:30-04:30 | L19: 04:30-06:00 | N19: not interested. | O19: NIL
A20: Shoaib | B20: 0349 5635598 | C20: 6 | D20: Not Attended | E20: Contacted | F20: 10:00 - 12:00 PM | G20: Not Recieved | H20: 12:00-02:30 | I20: Not Recieved | J20: 02:30-04:30 | L20: 04:30-06:00 | N20: had talked he said he didnt have any laptop or pc i asked him to find and let me know.( call him but he didnt recieved call) | O20: -
A21: Ibrahim | B21: 0310 5255500 | C21: 3 | D21: Call Attended | E21: Closed - Lost | F21: 10:00 - 12:00 PM | G21: Call Recieved | H21: 12:00-02:30 | I21: Not Recieved | J21: 02:30-04:30 | L21: 04:30-06:00 | N21: had talked with him told him about course he is interested but cant afford course i asked how much he can pay but he said he coudlnt pay. | O21: NIl
A22: Hadia | B22: 0331 5600623 | C22: 3 | D22: Not Attended | E22: Awaiting Response | F22: 10:00 - 12:00 PM | H22: 12:00-02:30 | I22: Not Recieved | J22: 02:30-04:30 | K22: Call Recieved | L22: 04:30-06:00 | N22: she is interested but she said on whtsapp her father is not convence for online course. moreover i asked her to make him convence. she would told me about today. | O22: reach her out again later.
A23: Hameedullah | B23: 0313 8978984 | C23: 6 | D23: Not Attended | E23: Awaiting Response | F23: 10:00 - 12:00 PM | G23: Not Recieved | H23: 12:00-02:30 | I23: Not Recieved | J23: 02:30-04:30 | L23: 04:30-06:00 | M23: Not Recieved | N23: he has done B.sc and want to start his career in tech industry thats why want to avail this course. will confirm in 1 or 2 days. ( not recieved call drop msg on whtsapp) still not responding | O23: reach out again later.
A24: Shahid | B24: 0328-2187990 | C24: 2 | D24: Call Attended | E24: Closed - Lost | F24: 10:00 - 12:00 PM | H24: 12:00-02:30 | I24: Call Recieved | J24: 02:30-04:30 | L24: 04:30-06:00 | M24: Call Recieved | N24: had talked with him he was looking for dropshipping .. not have any interest in this course. | O24: nil
A25: Babar | B25: 0348-9451791 | C25: 1 | D25: Call Attended | E25: Closed - Lost | F25: 10:00 - 12:00 PM | H25: 12:00-02:30 | J25: 02:30-04:30 | L25: 04:30-06:00 | M25: Call Recieved | N25: he has no money jobless lives in KPK want to learn this course in free cant pay one single peny as per his say. | O25: _
A26: Abuzar | B26: 0335-9161732 | C26: 2 | D26: Call Attended | E26: Closed - Lost | F26: 10:00 - 12:00 PM | H26: 12:00-02:30 | I26: Call Recieved | J26: 02:30-04:30 | L26: 04:30-06:00 | M26: Call Recieved | N26: had talked but they reacting like a stranger as they dont know about course or anything and last he said we dont want to enroll | O26: -
A27: Sarmad | B27: 0307-0004297 | C27: 3 | D27: Not Attended | E27: Awaiting Response | F27: 10:00 - 12:00 PM | H27: 12:00-02:30 | I27: Call Recieved | J27: 02:30-04:30 | L27: 04:30-06:00 | M27: Not Recieved | N27: he is in office said call me later ( didnt recieved call drop msg on whtsapp) | O27: call tomorrow
A28: Murtuza | B28: 92 300 2530903 | C28: 4 | D28: Not Attended | E28: Call not Recieved | F28: 10:00 - 12:00 PM | G28: Not Recieved | H28: 12:00-02:30 | I28: Not Recieved | J28: 02:30-04:30 | K28: Not Recieved | L28: 04:30-06:00 | M28: Not Recieved | N28: didn't pick up the call. didnt respond on whtsapp. | O28: NIL
A29: Zahid | B29: 92 343 8277690 | C29: 4 | D29: Not Attended | E29: Call not Recieved | F29: 10:00 - 12:00 PM | G29: Not Recieved | H29: 12:00-02:30 | I29: Not Recieved | J29: 02:30-04:30 | K29: Not Recieved | L29: 04:30-06:00 | M29: Not Recieved | N29: can't connect call drop msg on whtsapp but didnt reply. | O29: call him after 2 days
A30: Farhan | B30: 92 347 2694975 | C30: 1 | D30: Call Attended | E30: Closed - Lost | F30: 10:00 - 12:00 PM | H30: 12:00-02:30 | J30: 02:30-04:30 | K30: Call Recieved | L30: 04:30-06:00 | N30: Had talked with him he didnt have any pc or laptop said can i do it over phone / | O30: -
B31: 92 342 9105279 | C31: 3 | D31: Not Attended | E31: Call not Recieved | F31: 10:00 - 12:00 PM | G31: Not Recieved | H31: 12:00-02:30 | I31: Not Recieved | J31: 02:30-04:30 | K31: Not Recieved | L31: 04:30-06:00 | N31: Still not recieved call not replying on whtsapp. | O31: reach out again today
A32: Naeem | B32: 92 332 2735044 | C32: 2 | D32: Call Attended | E32: Closed - Lost | F32: 10:00 - 12:00 PM | H32: 12:00-02:30 | J32: 02:30-04:30 | K32: Call Recieved | L32: 04:30-06:00 | N32: call recieved but didnt talk properly and didnt understand anything about course | O32: NIL
A33: Arshad | B33: 92 327 1458765 | C33: 4 | D33: Not Attended | E33: Contacted | F33: 10:00 - 12:00 PM | G33: Not Recieved | H33: 12:00-02:30 | I33: Call Recieved | J33: 02:30-04:30 | K33: Not Recieved | L33: 04:30-06:00 | M33: Not Recieved | N33: had talked with him he said may b his bro generate query he said call me at 5 i will let you talk to my bro.( i call at 5 but he didnt pick up the call). didnt pick up the call not responding on whtsapp.) | O33: call him after 2 days
A34: Samra | B34: 92 344 4853224 | C34: 3 | D34: Not Attended | E34: Contacted | F34: 10:00 - 12:00 PM | G34: Not Recieved | H34: 12:00-02:30 | I34: Call Recieved | J34: 02:30-04:30 | K34: Please Call later | L34: 04:30-06:00 | N34: had talked i told her that she show interest in our course she hang up on me . drop msg on whtsapp. ( not attending call) | O34: reach out again today
A35: Hussain | B35: 92 304 8098804 | C35: 4 | D35: Not Attended | E35: Awaiting Response | F35: 10:00 - 12:00 PM | G35: Not Recieved | H35: 12:00-02:30 | J35: 02:30-04:30 | K35: Not Recieved | L35: 04:30-06:00 | N35: had talked with him he is interested share details of demo and bank he said he will review it & will confirm about payment.( didnt pick up the call drop msg on whtsapp) still not answering | O35: call him tomorrow.
A36: Yasir | B36: 92 332 5106008 | C36: 1 | D36: Not Attended | E36: Closed - Lost | F36: 10:00 - 12:00 PM | G36: Not Recieved | H36: 12:00-02:30 | J36: 02:30-04:30 | L36: 04:30-06:00 | N36: had talked on whtsapp bascially want job or want to reach our someone through our platform. not interested in course. | O36: NIL
A37: Irfan | B37: 92 342 0821163 | C37: 4 | D37: Call Attended | E37: Contacted | F37: 10:00 - 12:00 PM | G37: Not Recieved | H37: 12:00-02:30 | I37: Call Recieved | J37: 02:30-04:30 | K37: Call Recieved | L37: 04:30-06:00 | M37: Call Recieved | N37: had a little talk with him he said he is busy in office call him after office hours. | O37: call him after 6 pm
A38: Arsalan | B38: 92 333 7551611 | C38: 4 | D38: Not Attended | E38: Contacted | F38: 10:00 - 12:00 PM | G38: Not Recieved | H38: 12:00-02:30 | J38: 02:30-04:30 | K38: Not Recieved | L38: 04:30-06:00 | N38: had little talk on call as he was busy he said we will talk later. moreover i shared details with him. ( not attending call not respond on whtsapp). | O38: call today at 4
A39: Farhan | B39: 92 314 5001584 | C39: 5 | D39: Not Attended | E39: Contacted | F39: 10:00 - 12:00 PM | G39: Not Recieved | H39: 12:00-02:30 | J39: 02:30-04:30 | K39: Not Recieved | L39: 04:30-06:00 | M39: Not Recieved | N39: call but someone else pick up the call and said farhan is not at home i told him when he back tell him to cll me back.(not attend call not reply on whtsapp) | O39: call today at 4
A40: Shams | B40: 92 307 0079544 | C40: 2 | D40: Not Attended | E40: Contacted | F40: 10:00 - 12:00 PM | G40: Not Recieved | H40: 12:00-02:30 | I40: Call Recieved | J40: 02:30-04:30 | L40: 04:30-06:00 | N40: had talked he is in office said call me in evening moreover send details on whtsapp.( not attending call not reply on whtsapp). | O40: call in evening
...

Sheet 6
A1: Prospect Name | B1: Number | C1: Attempts Missing | D1: Status | E1: stage | F1: Call Slot 1 | G1: Attempt 1 | H1: Call Slot 2 | I1: Attempt 2 | J1: Call Slot 3 | K1: Attempt-3 | L1: Call Slot 4 | M1: Attempt-4 | N1: Lead Type | O1: Notes | P1: Next Step | Q1: date
B2: 92 333 3597982 | D2: Call Attended | E2: Awaiting Response | F2: 10:00 - 12:00 PM | G2: Call Recieved | H2: 12:00-02:30 | J2: 02:30-04:30 | L2: 04:30-06:00 | O2: will confirm me in 30 mins, call him back on 5th may
A3: Shoaib Malik | B3: 92 308 3635652 | D3: Call Attended | E3: Awaiting payment | F3: 10:00 - 12:00 PM | G3: Call Recieved | H3: 12:00-02:30 | J3: 02:30-04:30 | L3: 04:30-06:00 | O3: form filled, will pay fees till 6 june
B4: 92 309 7109717 | D4: Not Attended | E4: Contacted | F4: 10:00 - 12:00 PM | G4: Not Recieved | H4: 12:00-02:30 | I4: Call Recieved | J4: 02:30-04:30 | K4: Call Recieved | L4: 04:30-06:00 | M4: Not Recieved | O4: immediately cut the call
B5: 92 336 4429052 | D5: Not Attended | E5: Closed - Lost | F5: 10:00 - 12:00 PM | G5: Client lost | H5: 12:00-02:30 | I5: Client lost | J5: 02:30-04:30 | K5: Client lost | L5: 04:30-06:00 | M5: Client lost | O5: lost lead
B6: 92 336 8238809 | D6: Not Attended | E6: Contacted | F6: 10:00 - 12:00 PM | G6: Not Recieved | H6: 12:00-02:30 | I6: Not Recieved | J6: 02:30-04:30 | L6: 04:30-06:00 | M6: Call Recieved | O6: details shared again on whatsapp
B7: 92 355 4420566 | D7: Not Attended | E7: Call not Recieved | F7: 10:00 - 12:00 PM | G7: Not Recieved | H7: 12:00-02:30 | I7: Not Recieved | J7: 02:30-04:30 | K7: Not Recieved | L7: 04:30-06:00 | M7: Not Recieved | O7: no response
B8: 92 328 6000794 | D8: Not Attended | E8: Call not Recieved | F8: 10:00 - 12:00 PM | G8: Not Recieved | H8: 12:00-02:30 | I8: Not Recieved | J8: 02:30-04:30 | K8: Not Recieved | L8: 04:30-06:00 | M8: Not Recieved | O8: no response
B9: 92 340 0581572 | D9: Call Attended | E9: Awaiting Response | F9: 10:00 - 12:00 PM | G9: Call Recieved | H9: 12:00-02:30 | J9: 02:30-04:30 | K9: Call Recieved | L9: 04:30-06:00 | M9: Call Recieved | O9: details shared again on whatsapp
B10: 92 333 9712136 | D10: Call Attended | E10: Contacted | F10: 10:00 - 12:00 PM | G10: Call Recieved | H10: 12:00-02:30 | J10: 02:30-04:30 | K10: Not Recieved | L10: 04:30-06:00 | M10: Not Recieved | O10: he cut the call
B11: 92 341 0045963 | D11: Not Attended | E11: Closed - Lost | F11: 10:00 - 12:00 PM | G11: Client lost | H11: 12:00-02:30 | I11: Client lost | J11: 02:30-04:30 | K11: Client lost | L11: 04:30-06:00 | M11: Client lost | O11: lost lead
B12: 92 329 7685207 | D12: Not Attended | E12: Closed - Lost | F12: 10:00 - 12:00 PM | G12: Client lost | H12: 12:00-02:30 | I12: Client lost | J12: 02:30-04:30 | K12: Client lost | L12: 04:30-06:00 | M12: Client lost | O12: not interested
B13: 92 348 4534609 | D13: Not Attended | E13: Call not Recieved | F13: 10:00 - 12:00 PM | G13: Not Recieved | H13: 12:00-02:30 | I13: Not Recieved | J13: 02:30-04:30 | K13: Not Recieved | L13: 04:30-06:00 | M13: Not Recieved | O13: no response
B14: 92 319 0382503 | D14: Call Attended | E14: Closed - Lost | F14: 10:00 - 12:00 PM | G14: Client lost | H14: 12:00-02:30 | I14: Client lost | J14: 02:30-04:30 | K14: Client lost | L14: 04:30-06:00 | M14: Client lost | O14: lost lead
B15: 92 340 7363012 | D15: Not Attended | E15: Call not Recieved | F15: 10:00 - 12:00 PM | G15: Not Recieved | H15: 12:00-02:30 | I15: Not Recieved | J15: 02:30-04:30 | K15: Not Recieved | L15: 04:30-06:00 | M15: Not Recieved | O15: no response
B16: 92 331 8910393 | E16: Awaiting payment | F16: 10:00 - 12:00 PM | H16: 12:00-02:30 | J16: 02:30-04:30 | L16: 04:30-06:00 | O16: will pay fees after till 11 june
B17: 92 311 7576492 | D17: Not Attended | E17: Call not Recieved | F17: 10:00 - 12:00 PM | G17: Not Recieved | H17: 12:00-02:30 | I17: Not Recieved | J17: 02:30-04:30 | K17: Not Recieved | L17: 04:30-06:00 | M17: Not Recieved | O17: no response
B18: 92 301 6802186 | D18: Not Attended | E18: Contacted | F18: 10:00 - 12:00 PM | G18: Call Recieved | H18: 12:00-02:30 | I18: Not Recieved | J18: 02:30-04:30 | K18: Not Recieved | L18: 04:30-06:00 | M18: Not Recieved | O18: his brother allpied for the course
B19: 92 325 9206535 | D19: Not Attended | E19: Call not Recieved | F19: 10:00 - 12:00 PM | G19: Not Recieved | H19: 12:00-02:30 | I19: Not Recieved | J19: 02:30-04:30 | K19: Not Recieved | L19: 04:30-06:00 | M19: Not Recieved | O19: no response
B20: 92 340 5544831 | D20: Call Attended | E20: Awaiting Response | F20: 10:00 - 12:00 PM | H20: 12:00-02:30 | I20: Call Recieved | J20: 02:30-04:30 | L20: 04:30-06:00 | O20: details shared again on whatsapp
B21: 92 332 1626073 | D21: Not Attended | E21: Call not Recieved | F21: 10:00 - 12:00 PM | G21: Not Recieved | H21: 12:00-02:30 | I21: Not Recieved | J21: 02:30-04:30 | K21: Not Recieved | L21: 04:30-06:00 | M21: Not Recieved | O21: no response
B22: 92 315 3721344 | D22: Not Attended | E22: Call not Recieved | F22: 10:00 - 12:00 PM | G22: Not Recieved | H22: 12:00-02:30 | I22: Not Recieved | J22: 02:30-04:30 | K22: Not Recieved | L22: 04:30-06:00 | M22: Not Recieved | O22: no response
A23: Khansa ch | B23: 92 305 6189462 | D23: Call Attended | E23: Closed - Lost | F23: 10:00 - 12:00 PM | G23: Client lost | H23: 12:00-02:30 | I23: Client lost | J23: 02:30-04:30 | K23: Client lost | L23: 04:30-06:00 | M23: Client lost | O23: blocked me after see the price
B24: 92 313 1347114 | D24: Not Attended | E24: Call not Recieved | F24: 10:00 - 12:00 PM | G24: Not Recieved | H24: 12:00-02:30 | I24: Not Recieved | J24: 02:30-04:30 | K24: Not Recieved | L24: 04:30-06:00 | M24: Not Recieved | O24: no response
B25: 92 314 1272749 | E25: enroll in next batch | F25: 10:00 - 12:00 PM | H25: 12:00-02:30 | J25: 02:30-04:30 | L25: 04:30-06:00 | O25: cannot attend classes because of finals
B26: 92 319 6934822 | D26: Not Attended | E26: Closed - Lost | F26: 10:00 - 12:00 PM | G26: Client lost | H26: 12:00-02:30 | I26: Client lost | J26: 02:30-04:30 | K26: Client lost | L26: 04:30-06:00 | M26: Client lost | O26: lost lead
B27: 92 342 1213536 | D27: Not Attended | E27: Closed - Lost | F27: 10:00 - 12:00 PM | G27: Client lost | H27: 12:00-02:30 | I27: Client lost | J27: 02:30-04:30 | K27: Client lost | L27: 04:30-06:00 | M27: Client lost | O27: not interested in data science
B28: 92 349 1836928 | D28: Not Attended | E28: Call not Recieved | F28: 10:00 - 12:00 PM | G28: Not Recieved | H28: 12:00-02:30 | I28: Not Recieved | J28: 02:30-04:30 | K28: Not Recieved | L28: 04:30-06:00 | M28: Not Recieved | O28: no response
B29: 92 340 6508936 | D29: Call Attended | E29: Closed - Lost | F29: 10:00 - 12:00 PM | G29: Client lost | H29: 12:00-02:30 | I29: Client lost | J29: 02:30-04:30 | K29: Client lost | L29: 04:30-06:00 | M29: Client lost | O29: details again shared on whatsapp
A30: Aiman | B30: 92 312 5592849 | D30: Not Attended | E30: demo | F30: 10:00 - 12:00 PM | G30: Not Recieved | H30: 12:00-02:30 | I30: Not Recieved | J30: 02:30-04:30 | K30: Not Recieved | L30: 04:30-06:00 | M30: Not Recieved | O30: no response
B31: 92 304 1282405 | D31: Not Attended | E31: Call not Recieved | F31: 10:00 - 12:00 PM | G31: Not Recieved | H31: 12:00-02:30 | I31: Not Recieved | J31: 02:30-04:30 | K31: Not Recieved | L31: 04:30-06:00 | M31: Not Recieved | O31: no response
B32: 92 301 3283498 | D32: Call Attended | E32: Awaiting Response | F32: 10:00 - 12:00 PM | H32: 12:00-02:30 | I32: Call Recieved | J32: 02:30-04:30 | L32: 04:30-06:00 | O32: rn he's in a village, he'll confirm me once he come to the city
B33: 92 300 8797662 | D33: Not Attended | E33: Call not Recieved | F33: 10:00 - 12:00 PM | G33: Not Recieved | H33: 12:00-02:30 | I33: Not Recieved | J33: 02:30-04:30 | K33: Not Recieved | L33: 04:30-06:00 | M33: Not Recieved | O33: no response
B34: 92 342 6064181 | D34: Call Attended | E34: Closed - Lost | F34: 10:00 - 12:00 PM | G34: Client lost | H34: 12:00-02:30 | I34: Client lost | J34: 02:30-04:30 | K34: Client lost | L34: 04:30-06:00 | M34: Client lost | O34: lost lead
B35: 92 325 5171370 | D35: Call Attended | E35: Contacted | F35: 10:00 - 12:00 PM | G35: Call Recieved | H35: 12:00-02:30 | I35: Call Recieved | J35: 02:30-04:30 | K35: Not Recieved | L35: 04:30-06:00 | M35: Not Recieved | O35: Will fill form
A36: Shahzina shahbaz | B36: 92 309 6144786 | D36: Call Attended | E36: form filled | F36: 10:00 - 12:00 PM | G36: Call Recieved | H36: 12:00-02:30 | I36: Not Recieved | J36: 02:30-04:30 | L36: 04:30-06:00 | M36: Not Recieved | O36: she's not at home
B37: 92 319 7634505 | D37: Call Attended | E37: Awaiting Response | F37: 10:00 - 12:00 PM | H37: 12:00-02:30 | I37: Call Recieved | J37: 02:30-04:30 | L37: 04:30-06:00 | O37: busy in exams. will contact him again on 16th june
B38: 92 324 9506696 | D38: Call Attended | E38: Awaiting Response | F38: 10:00 - 12:00 PM | H38: 12:00-02:30 | I38: Call Recieved | J38: 02:30-04:30 | L38: 04:30-06:00 | O38: will confirm me by today evening
B39: 92 320 7433220 | D39: Call Attended | E39: Closed - Lost | F39: 10:00 - 12:00 PM | G39: Client lost | H39: 12:00-02:30 | I39: Client lost | J39: 02:30-04:30 | K39: Client lost | L39: 04:30-06:00 | M39: Client lost | O39: not interested
B40: 92 325 8804362 | D40: Not Attended | E40: Closed - Lost | F40: 10:00 - 12:00 PM | G40: Client lost | H40: 12:00-02:30 | I40: Client lost | J40: 02:30-04:30 | K40: Client lost | L40: 04:30-06:00 | M40: Client lost | O40: not interested in data science and AI course
...

Sheet Sheet10
A1: Name | B1: Phone Number
A2: Samra | B2: 92 344 4853224
A3: Hadia | B3: 0331 5600623
A4: Shams | B4: 92 307 0079544
A5: Unknown-2 | B5: 0347-3063900
A6: Mamoona | B6: 0347-2292892
A7: Ahmed | B7: 0320-7807857
A8: Unknown-4 | B8: 0330-8675442
A9: Dr Farzana | B9: 92 332 3633535
A10: Irfan | B10: 92 342 0821163
A11: Farhan | B11: 92 314 5001584
A12: Unknown-6 | B12: 92 336 6222293
... A42: Wasif | B42: 92 332 5130344

Sheet Sheet11
A1: 92 314 2639113
A2: 92 301 2073908
A3: 0311 1575311
A4: 0332 3740133
A5: 0329 8167660
A6: 0300 7872645
A7: 0317 0920130
A8: 0331 2133552
A9: 0308 2181928
A10: 0333 0218820
A11: 0347 3786945
A12: 0300 5447177
... A130: 0344 4045609

Sheet 1
A1: Prospect Name | B1: Number | C1: Attempts done | D1: Status | E1: stage | F1: Call Slot 1 | G1: Attempt 1 | H1: Call Slot 2 | I1: Attempt 2 | J1: Call Slot 3 | K1: Attempt-3 | L1: Call Slot 4 | M1: Attempt-4 | N1: Notes | O1: Next Step | P1: Column 1
A2: zulfiqar Ali | B2: 0328 4781718 | C2: =COUNTIF(G2:M2, "Not attempted") + COUNTIF(G2:M2, "Not Recieved") -> 0 | D2: Call Attended | E2: Closed - Lost | F2: 10:00 - 12:00 PM | G2: Client lost | H2: 12:00-02:30 | I2: Call Recieved | J2: 02:30-04:30 | K2: Client lost | L2: 04:30-06:00 | M2: Client lost | N2: lost lead
A3: muhaamad zeeshan | B3: 0348 0619993 | C3: =COUNTIF(G3:M3, "Not attempted") + COUNTIF(G3:M3, "Not Recieved") -> 2 | D3: Call Attended | E3: Contacted | F3: 10:00 - 12:00 PM | G3: Call Recieved | H3: 12:00-02:30 | I3: Not Recieved | J3: 02:30-04:30 | K3: Call Recieved | L3: 04:30-06:00 | M3: Not Recieved | N3: will inform by today evening
B4: 0348 8915568/ 0313 0159585 | C4: =COUNTIF(G4:M4, "Not attempted") + COUNTIF(G4:M4, "Not Recieved") -> 1 | D4: Call Attended | E4: Closed - Won | F4: 10:00 - 12:00 PM | G4: Call Recieved | H4: 12:00-02:30 | I4: Call Recieved | J4: 02:30-04:30 | K4: Not Recieved | L4: 04:30-06:00 | M4: Call Recieved | N4: paid
A5: Unknown | B5: 0336 6491115 | C5: =COUNTIF(G5:M5, "Not attempted") + COUNTIF(G5:M5, "Not Recieved") -> 0 | D5: Call Attended | E5: Closed - Lost | F5: 10:00 - 12:00 PM | G5: Client lost | H5: 12:00-02:30 | I5: Call Recieved | J5: 02:30-04:30 | K5: Client lost | L5: 04:30-06:00 | M5: Client lost | N5: lost lead
A6: Unknown | B6: 0346 7124633 | C6: =COUNTIF(G6:M6, "Not attempted") + COUNTIF(G6:M6, "Not Recieved") -> 2 | D6: Call Attended | E6: Closed - Lost | F6: 10:00 - 12:00 PM | G6: Call Recieved | H6: 12:00-02:30 | I6: Not attempted | J6: 02:30-04:30 | K6: Call Recieved | L6: 04:30-06:00 | M6: Not attempted | N6: lost lead
A7: muhammad sohail | B7: 0333 6900114 | C7: =COUNTIF(G7:M7, "Not attempted") + COUNTIF(G7:M7, "Not Recieved") -> 0 | D7: Call Attended | E7: Closed - Lost | F7: 10:00 - 12:00 PM | G7: Call Recieved | H7: 12:00-02:30 | I7: Call Recieved | J7: 02:30-04:30 | K7: Call Recieved | L7: 04:30-06:00 | M7: Call Recieved | N7: lost lead
A8: Unknown | B8: 0316 1316907 | C8: =COUNTIF(G8:M8, "Not attempted") + COUNTIF(G8:M8, "Not Recieved") -> 0 | D8: Call Attended | E8: Closed - Lost | F8: 10:00 - 12:00 PM | G8: Client lost | H8: 12:00-02:30 | I8: Call Recieved | J8: 02:30-04:30 | K8: Client lost | L8: 04:30-06:00 | M8: Client lost | N8: lost lead
A9: Unknown | B9: 0319 3509440 | C9: =COUNTIF(G9:M9, "Not attempted") + COUNTIF(G9:M9, "Not Recieved") -> 0 | D9: Call Attended | E9: Closed - Lost | G9: Client lost | I9: Client lost | K9: Call Recieved | M9: Client lost | N9: lost lead
A10: Aftab Ashiq | B10: 0345 9208701 | C10: =COUNTIF(G10:M10, "Not attempted") + COUNTIF(G10:M10, "Not Recieved") -> 1 | D10: Call Attended | E10: Closed - Lost | F10: 10:00 - 12:00 PM | G10: Client lost | H10: 12:00-02:30 | I10: Call Recieved | J10: 02:30-04:30 | K10: Not Recieved | L10: 04:30-06:00 | M10: Client lost | N10: lost lead
B11: 0300 4754980 | C11: =COUNTIF(G11:M11, "Not attempted") + COUNTIF(G11:M11, "Not Recieved") -> 1 | D11: Call Attended | E11: Closed - Won | F11: 10:00 - 12:00 PM | G11: Call Recieved | H11: 12:00-02:30 | I11: Not Recieved | J11: 02:30-04:30 | K11: Call Recieved | L11: 04:30-06:00 | M11: Call Recieved | N11: pay by 25
A12: Unknown | B12: 0307 8647992 | C12: =COUNTIF(G12:M12, "Not attempted") + COUNTIF(G12:M12, "Not Recieved") -> 1 | D12: Call Attended | E12: Closed - Lost | F12: 10:00 - 12:00 PM | G12: Call Recieved | H12: 12:00-02:30 | I12: Call Recieved | J12: 02:30-04:30 | K12: Call Recieved | L12: 04:30-06:00 | M12: Not Recieved | N12: lost lead
A13: Unknown | B13: 0332 3154075 | C13: =COUNTIF(G13:M13, "Not attempted") + COUNTIF(G13:M13, "Not Recieved") -> 1 | D13: Not Attended | E13: Closed - Lost | F13: 10:00 - 12:00 PM | G13: Not Recieved | H13: 12:00-02:30 | I13: Client lost | J13: 02:30-04:30 | K13: Client lost | L13: 04:30-06:00 | M13: Client lost | N13: lost lead
A14: Unknown | B14: 0322 7567955 | C14: =COUNTIF(G14:M14, "Not attempted") + COUNTIF(G14:M14, "Not Recieved") -> 3 | D14: Call Attended | E14: Closed - Won | F14: 10:00 - 12:00 PM | G14: Not Recieved | H14: 12:00-02:30 | I14: Call Recieved | J14: 02:30-04:30 | K14: Not Recieved | L14: 04:30-06:00 | M14: Not Recieved | N14: no response
A15: Unknown | B15: 0319 8046813 | C15: =COUNTIF(G15:M15, "Not attempted") + COUNTIF(G15:M15, "Not Recieved") -> 0 | D15: Call Attended | E15: Closed - Lost | F15: 10:00 - 12:00 PM | G15: Call Recieved | H15: 12:00-02:30 | I15: Call Recieved | J15: 02:30-04:30 | K15: Client lost | L15: 04:30-06:00 | M15: Client lost | N15: lost lead
A16: Huzaifa | B16: 0336 2333934/ 0336 2333933 | C16: =COUNTIF(G16:M16, "Not attempted") + COUNTIF(G16:M16, "Not Recieved") -> 0 | D16: Call Attended | E16: Closed - Won | F16: 10:00 - 12:00 PM | G16: Call Recieved | H16: 12:00-02:30 | I16: Call Recieved | J16: 02:30-04:30 | K16: Call Recieved | L16: 04:30-06:00 | M16: Call Recieved | N16: paid
A17: Unknown | B17: 0312 9061344 | C17: =COUNTIF(G17:M17, "Not attempted") + COUNTIF(G17:M17, "Not Recieved") -> 2 | D17: Call Attended | E17: Demo | F17: 10:00 - 12:00 PM | G17: Not Recieved | H17: 12:00-02:30 | I17: Please Call later | J17: 02:30-04:30 | K17: Not Recieved | L17: 04:30-06:00 | M17: Call Recieved | N17: demo then decide
A18: Unknown | B18: 0342 0475836 | C18: =COUNTIF(G18:M18, "Not attempted") + COUNTIF(G18:M18, "Not Recieved") -> 0 | D18: Call Attended | E18: Closed - Lost | F18: 10:00 - 12:00 PM | G18: Call Recieved | H18: 12:00-02:30 | I18: Call Recieved | J18: 02:30-04:30 | K18: Client lost | L18: 04:30-06:00 | M18: Client lost | N18: lost lead
A19: Unknown | B19: 0355 5647456/ 0341 8993261 | C19: =COUNTIF(G19:M19, "Not attempted") + COUNTIF(G19:M19, "Not Recieved") -> 1 | D19: Call Attended | E19: Closed - Lost | F19: 10:00 - 12:00 PM | G19: Client lost | H19: 12:00-02:30 | I19: Client lost | J19: 02:30-04:30 | K19: Client lost | L19: 04:30-06:00 | M19: Not Recieved | N19: lost lead
A20: Unknown | B20: 0343 5585163 | C20: =COUNTIF(G20:M20, "Not attempted") + COUNTIF(G20:M20, "Not Recieved") -> 0 | D20: Call Attended | E20: Closed - Lost | F20: 10:00 - 12:00 PM | G20: Call Recieved | H20: 12:00-02:30 | I20: Client lost | J20: 02:30-04:30 | K20: Client lost | L20: 04:30-06:00 | M20: Client lost | N20: lost lead
B21: 0308 0864165 | C21: =COUNTIF(G21:M21, "Not attempted") + COUNTIF(G21:M21, "Not Recieved") -> 3 | D21: Call Attended | E21: Closed - Lost | F21: 10:00 - 12:00 PM | G21: Not Recieved | H21: 12:00-02:30 | I21: Call Recieved | J21: 02:30-04:30 | K21: Not Recieved | L21: 04:30-06:00 | M21: Not Recieved | N21: lost lead
B22: 0333 2366141 | C22: =COUNTIF(G22:M22, "Not attempted") + COUNTIF(G22:M22, "Not Recieved") -> 1 | D22: Call Attended | E22: Closed - Lost | F22: 10:00 - 12:00 PM | G22: Please Call later | H22: 12:00-02:30 | I22: Not Recieved | J22: 02:30-04:30 | K22: Call Recieved | L22: 04:30-06:00 | M22: Call Recieved | N22: lost lead
A23: Unknown | B23: 0314 8380754 | C23: =COUNTIF(G23:M23, "Not attempted") + COUNTIF(G23:M23, "Not Recieved") -> 1 | D23: Call Attended | E23: Closed - Lost | F23: 10:00 - 12:00 PM | G23: Client lost | H23: 12:00-02:30 | I23: Not Recieved | J23: 02:30-04:30 | K23: Please Call later | L23: 04:30-06:00 | M23: Client lost | N23: lost lead
A24: Unknown | B24: 0326 9784378 | C24: =COUNTIF(G24:M24, "Not attempted") + COUNTIF(G24:M24, "Not Recieved") -> 0 | D24: Call Attended | E24: Closed - Lost | F24: 10:00 - 12:00 PM | G24: Client lost | H24: 12:00-02:30 | I24: Call Recieved | J24: 02:30-04:30 | K24: Client lost | L24: 04:30-06:00 | M24: Client lost | N24: lost lead
A25: Unknown | B25: 0313 1160140 | C25: =COUNTIF(G25:M25, "Not attempted") + COUNTIF(G25:M25, "Not Recieved") -> 4 | D25: Call Attended | E25: Contacted | F25: 10:00 - 12:00 PM | G25: Not Recieved | H25: 12:00-02:30 | I25: Not Recieved | J25: 02:30-04:30 | K25: Not Recieved | L25: 04:30-06:00 | M25: Not Recieved | N25: no response
A26: Unknown | B26: 0312 1640492 | C26: =COUNTIF(G26:M26, "Not attempted") + COUNTIF(G26:M26, "Not Recieved") -> 0 | D26: Call Attended | E26: Closed - Lost | F26: 10:00 - 12:00 PM | G26: Client lost | H26: 12:00-02:30 | I26: Call Recieved | J26: 02:30-04:30 | K26: Client lost | L26: 04:30-06:00 | M26: Client lost | N26: lost lead
A27: saddiqa | B27: 0333 2351659 | C27: =COUNTIF(G27:M27, "Not attempted") + COUNTIF(G27:M27, "Not Recieved") -> 2 | D27: Call Attended | E27: Closed - Lost | F27: 10:00 - 12:00 PM | G27: Call Recieved | H27: 12:00-02:30 | I27: Not Recieved | J27: 02:30-04:30 | K27: Call Recieved | L27: 04:30-06:00 | M27: Not Recieved | N27: lost lead
A28: Unknown | B28: 0340 5160363 | C28: =COUNTIF(G28:M28, "Not attempted") + COUNTIF(G28:M28, "Not Recieved") -> 1 | D28: Not Attended | E28: Closed - Lost | F28: 10:00 - 12:00 PM | G28: Not Recieved | H28: 12:00-02:30 | I28: Client lost | J28: 02:30-04:30 | K28: Client lost | L28: 04:30-06:00 | M28: Client lost | N28: lost lead
A29: Unknown | B29: 0332 6400818 | C29: =COUNTIF(G29:M29, "Not attempted") + COUNTIF(G29:M29, "Not Recieved") -> 2 | D29: Call Attended | E29: Closed - Lost | F29: 10:00 - 12:00 PM | G29: Client lost | H29: 12:00-02:30 | I29: Call Recieved | J29: 02:30-04:30 | K29: Not Recieved | L29: 04:30-06:00 | M29: Not Recieved | N29: lost lead
A30: Unknown | B30: 0314 9716172 | C30: =COUNTIF(G30:M30, "Not attempted") + COUNTIF(G30:M30, "Not Recieved") -> 0 | D30: Call Attended | E30: Awaiting Response | F30: 10:00 - 12:00 PM | G30: Call Recieved | H30: 12:00-02:30 | I30: Call Recieved | J30: 02:30-04:30 | K30: Call Recieved | L30: 04:30-06:00 | M30: Call Recieved | N30: interested, need discount
A31: Unknown | B31: 0355 4350784 | C31: =COUNTIF(G31:M31, "Not attempted") + COUNTIF(G31:M31, "Not Recieved") -> 0 | D31: Call Attended | E31: Closed - Lost | F31: 10:00 - 12:00 PM | G31: Client lost | H31: 12:00-02:30 | I31: Client lost | J31: 02:30-04:30 | K31: Call Recieved | L31: 04:30-06:00 | M31: Client lost | N31: need free course
B32: 0330 9865000 | C32: =COUNTIF(G32:M32, "Not attempted") + COUNTIF(G32:M32, "Not Recieved") -> 2 | D32: Call Attended | E32: Closed - Lost | F32: 10:00 - 12:00 PM | G32: Not Recieved | H32: 12:00-02:30 | I32: Call Recieved | J32: 02:30-04:30 | K32: Call Recieved | L32: 04:30-06:00 | M32: Not attempted | N32: lost leafd
A33: Unknown | B33: 0304 8200211 | C33: =COUNTIF(G33:M33, "Not attempted") + COUNTIF(G33:M33, "Not Recieved") -> 1 | D33: Call Attended | E33: Closed - Lost | F33: 10:00 - 12:00 PM | G33: Client lost | H33: 12:00-02:30 | I33: Client lost | J33: 02:30-04:30 | K33: Client lost | L33: 04:30-06:00 | M33: Not Recieved | N33: lost lead
B34: 0307 9143435 | C34: =COUNTIF(G34:M34, "Not attempted") + COUNTIF(G34:M34, "Not Recieved") -> 0 | D34: Call Attended | E34: Closed - Won | F34: 10:00 - 12:00 PM | G34: Call Recieved | H34: 12:00-02:30 | I34: Call Recieved | J34: 02:30-04:30 | K34: Call Recieved | L34: 04:30-06:00 | M34: Call Recieved | N34: paid
A35: Unknown | B35: 0309 5771866 | C35: =COUNTIF(G35:M35, "Not attempted") + COUNTIF(G35:M35, "Not Recieved") -> 4 | D35: Call Attended | E35: Closed - Lost | F35: 10:00 - 12:00 PM | G35: Not Recieved | H35: 12:00-02:30 | I35: Not Recieved | J35: 02:30-04:30 | K35: Not Recieved | L35: 04:30-06:00 | M35: Not Recieved | N35: lost lead
A36: Unknown | B36: 0314 1014974 | C36: =COUNTIF(G36:M36, "Not attempted") + COUNTIF(G36:M36, "Not Recieved") -> 0 | D36: Call Attended | E36: Closed - Lost | F36: 10:00 - 12:00 PM | G36: Client lost | H36: 12:00-02:30 | I36: Client lost | J36: 02:30-04:30 | K36: Client lost | L36: 04:30-06:00 | M36: Client lost | N36: lost lead
A37: Unknown | B37: 0345 6663161 | C37: =COUNTIF(G37:M37, "Not attempted") + COUNTIF(G37:M37, "Not Recieved") -> 0 | D37: Call Attended | E37: Closed - Lost | F37: 10:00 - 12:00 PM | G37: Call Recieved | H37: 12:00-02:30 | I37: Client lost | J37: 02:30-04:30 | K37: Client lost | L37: 04:30-06:00 | M37: Client lost | N37: lost lead
A38: Tabinda | B38: 0333 2354410 | C38: =COUNTIF(G38:M38, "Not attempted") + COUNTIF(G38:M38, "Not Recieved") -> 3 | D38: Call Attended | E38: Closed - Won | F38: 10:00 - 12:00 PM | G38: Call Recieved | H38: 12:00-02:30 | I38: Not Recieved | J38: 02:30-04:30 | K38: Not Recieved | L38: 04:30-06:00 | M38: Not Recieved | N38: interested will join | O38: will inform
A39: Unknown | B39: 0324 3649217 | C39: =COUNTIF(G39:M39, "Not attempted") + COUNTIF(G39:M39, "Not Recieved") -> 0 | D39: Not Attended | E39: Closed - Lost | F39: 10:00 - 12:00 PM | G39: Client lost | H39: 12:00-02:30 | I39: Client lost | J39: 02:30-04:30 | K39: Client lost | L39: 04:30-06:00 | M39: Client lost | N39: lost lead
A40: Unknown | B40: 0300 3599194 | C40: =COUNTIF(G40:M40, "Not attempted") + COUNTIF(G40:M40, "Not Recieved") -> 0 | D40: Call Attended | E40: Closed - Lost | F40: 10:00 - 12:00 PM | G40: Client lost | H40: 12:00-02:30 | I40: Call Recieved | J40: 02:30-04:30 | K40: Client lost | L40: 04:30-06:00 | M40: Client lost | N40: lost lead
...

Sheet 2
A1: Prospect Name | B1: Number | C1: Attempts Missing | D1: Status | E1: stage | F1: Call Slot 1 | G1: Attempt 1 | H1: Call Slot 2 | I1: Attempt 2 | J1: Call Slot 3 | K1: Attempt-3 | L1: Call Slot 4 | M1: Attempt-4 | N1: Lead Type | O1: Notes | P1: Next Step | Q1: date
B2: 92 331 8293629 | C2: =COUNTIF(G2:M2, "Not attempted") -> 0 | D2: Call Attended | E2: Closed - Lost | F2: 10:00 - 12:00 PM | G2: Client lost | H2: 12:00-02:30 | I2: Client lost | J2: 02:30-04:30 | K2: Client lost | L2: 04:30-06:00 | M2: Client lost | O2: busy, already enrolled in any other course | Q2: 14-5-2025
B3: 92 342 1691429 | C3: =COUNTIF(G3:M3, "Not attempted") -> 0 | D3: Call Attended | E3: Closed - Lost | F3: 10:00 - 12:00 PM | G3: Client lost | H3: 12:00-02:30 | I3: Client lost | J3: 02:30-04:30 | K3: Client lost | L3: 04:30-06:00 | M3: Client lost | O3: not interested. | Q3: 14-5-2025
B4: 92 340 8913963 | C4: =COUNTIF(G4:M4, "Not attempted") -> 0 | D4: Not Attended | E4: Closed - Lost | F4: 10:00 - 12:00 PM | G4: Client lost | H4: 12:00-02:30 | I4: Client lost | J4: 02:30-04:30 | K4: Client lost | L4: 04:30-06:00 | M4: Client lost | O4: cannot afford the course. | Q4: 14-5-2025
B5: 92 304 7107981 | C5: =COUNTIF(G5:M5, "Not attempted") -> 0 | D5: Not Attended | E5: Call not Recieved | F5: 10:00 - 12:00 PM | G5: Not Recieved | H5: 12:00-02:30 | I5: Not Recieved | J5: 02:30-04:30 | K5: Not Recieved | L5: 04:30-06:00 | M5: Not Recieved | O5: no response | Q5: 14-5-2025
B6: 92 311 2410698 | C6: =COUNTIF(G6:M6, "Not attempted") -> 0 | D6: Not Attended | E6: Call not Recieved | F6: 10:00 - 12:00 PM | G6: Not Recieved | H6: 12:00-02:30 | I6: Not Recieved | J6: 02:30-04:30 | K6: Not Recieved | L6: 04:30-06:00 | M6: Not Recieved | O6: no response | Q6: 14-5-2025
B7: 92 347 7491762 | C7: =COUNTIF(G7:M7, "Not attempted") -> 1 | D7: Call Attended | E7: enroll in next batch | F7: 10:00 - 12:00 PM | G7: Call Recieved | H7: 12:00-02:30 | I7: Client lost | J7: 02:30-04:30 | K7: Not attempted | L7: 04:30-06:00 | M7: Client lost | O7: busy now. enroll in next batch. | Q7: 14-5-2025
B8: 92 316 1615889 | C8: =COUNTIF(G8:M8, "Not attempted") -> 0 | D8: Call Attended | E8: Closed - Lost | F8: 10:00 - 12:00 PM | G8: Client lost | H8: 12:00-02:30 | I8: Client lost | J8: 02:30-04:30 | K8: Client lost | L8: 04:30-06:00 | M8: Client lost | O8: currently enrolled in marketing course. will join next batch | Q8: 14-5-2025
B9: 92 301 7920441 | C9: =COUNTIF(G9:M9, "Not attempted") -> 0 | D9: Call Attended | E9: Closed - Lost | F9: 10:00 - 12:00 PM | G9: Client lost | H9: 12:00-02:30 | I9: Client lost | J9: 02:30-04:30 | K9: Client lost | L9: 04:30-06:00 | M9: Client lost | O9: not interested, he is interested in onsite classes | Q9: 14-5-2025
B10: 92 334 7777851 | C10: =COUNTIF(G10:M10, "Not attempted") -> 0 | D10: Not Attended | E10: Call not Recieved | F10: 10:00 - 12:00 PM | G10: Not Recieved | H10: 12:00-02:30 | I10: Not Recieved | J10: 02:30-04:30 | K10: Not Recieved | L10: 04:30-06:00 | M10: Not Recieved | O10: no response | Q10: 14-5-2025
B11: 92 334 4377598 | C11: =COUNTIF(G11:M11, "Not attempted") -> 4 | D11: Call Attended | E11: Closed - Won | F11: 10:00 - 12:00 PM | G11: Not attempted | H11: 12:00-02:30 | I11: Not attempted | J11: 02:30-04:30 | K11: Not attempted | L11: 04:30-06:00 | M11: Not attempted | N11: qualified | O11: paid | Q11: 14-5-2025
B12: 92 312 3593749 | C12: =COUNTIF(G12:M12, "Not attempted") -> 0 | D12: Call Attended | E12: Closed - Lost | F12: 10:00 - 12:00 PM | G12: Client lost | H12: 12:00-02:30 | I12: Client lost | J12: 02:30-04:30 | K12: Client lost | L12: 04:30-06:00 | M12: Client lost | O12: her son doesn't allow her for the course | Q12: 14-5-2025
B13: 92 323 7001233 | C13: =COUNTIF(G13:M13, "Not attempted") -> 0 | D13: Not Attended | E13: Call not Recieved | F13: 10:00 - 12:00 PM | G13: Not Recieved | H13: 12:00-02:30 | I13: Not Recieved | J13: 02:30-04:30 | K13: Not Recieved | L13: 04:30-06:00 | M13: Not Recieved | O13: no response | Q13: 14-5-2025
B14: 92 303 4523810 | C14: =COUNTIF(G14:M14, "Not attempted") -> 0 | D14: Call Attended | E14: Closed - Lost | F14: 10:00 - 12:00 PM | G14: Client lost | H14: 12:00-02:30 | I14: Client lost | J14: 02:30-04:30 | K14: Client lost | L14: 04:30-06:00 | M14: Client lost | O14: cannot afford the course. | Q14: 14-5-2025
B15: 92 326 9507624 | C15: =COUNTIF(G15:M15, "Not attempted") -> 0 | D15: Not Attended | E15: Closed - Lost | F15: 10:00 - 12:00 PM | G15: Client lost | H15: 12:00-02:30 | I15: Client lost | J15: 02:30-04:30 | K15: Client lost | L15: 04:30-06:00 | M15: Client lost | O15: not interested, he is interested in onsite classes | Q15: 14-5-2025
B16: 92 341 8194127 | C16: =COUNTIF(G16:M16, "Not attempted") -> 0 | D16: Call Attended | E16: Contacted | F16: 10:00 - 12:00 PM | G16: Not Recieved | H16: 12:00-02:30 | I16: Please Call later | J16: 02:30-04:30 | K16: Not Recieved | L16: 04:30-06:00 | M16: Not Recieved | O16: awaiting response/ not reachable. | Q16: 14-5-2025
B17: 92 335 3483018 | C17: =COUNTIF(G17:M17, "Not attempted") -> 0 | D17: Not Attended | E17: Call not Recieved | F17: 10:00 - 12:00 PM | G17: Not Recieved | H17: 12:00-02:30 | I17: Not Recieved | J17: 02:30-04:30 | K17: Not Recieved | L17: 04:30-06:00 | M17: Not Recieved | O17: no response | Q17: 14-5-2025
B18: 92 320 7448330 | C18: =COUNTIF(G18:M18, "Not attempted") -> 0 | D18: Not Attended | E18: Call not Recieved | F18: 10:00 - 12:00 PM | G18: Not Recieved | H18: 12:00-02:30 | I18: Not Recieved | J18: 02:30-04:30 | K18: Not Recieved | L18: 04:30-06:00 | M18: Not Recieved | O18: no response | Q18: 14-5-2025
B19: 92 355 4741513 | C19: =COUNTIF(G19:M19, "Not attempted") -> 0 | D19: Not Attended | E19: Call not Recieved | F19: 10:00 - 12:00 PM | G19: Not Recieved | H19: 12:00-02:30 | I19: Not Recieved | J19: 02:30-04:30 | K19: Not Recieved | L19: 04:30-06:00 | M19: Not Recieved | O19: no response | Q19: 14-5-2025
B20: 92 335 0045016 | C20: =COUNTIF(G20:M20, "Not attempted") -> 1 | D20: Call Attended | E20: Closed - Lost | F20: 10:00 - 12:00 PM | G20: Not Recieved | H20: 12:00-02:30 | I20: Not Recieved | J20: 02:30-04:30 | K20: Call Recieved | L20: 04:30-06:00 | M20: Not attempted | N20: qualified | O20: cannot possible because of her personal issues. | Q20: 14-5-2025
B21: 92 347 8264716 | C21: =COUNTIF(G21:M21, "Not attempted") -> 0 | D21: Not Attended | E21: Call not Recieved | F21: 10:00 - 12:00 PM | G21: Not Recieved | H21: 12:00-02:30 | I21: Not Recieved | J21: 02:30-04:30 | K21: Not Recieved | L21: 04:30-06:00 | M21: Not Recieved | O21: no response | Q21: 14-5-2025
B22: 92 315 8057419 | C22: =COUNTIF(G22:M22, "Not attempted") -> 0 | D22: Call Attended | E22: Closed - Lost | F22: 10:00 - 12:00 PM | G22: Client lost | H22: 12:00-02:30 | I22: Client lost | J22: 02:30-04:30 | K22: Client lost | L22: 04:30-06:00 | M22: Client lost | O22: He's in a school, he doesn't have a pc or laptop | Q22: 14-5-2025
B23: 92 312 3593749 | C23: =COUNTIF(G23:M23, "Not attempted") -> 0 | D23: Not Attended | E23: Closed - Lost | F23: 10:00 - 12:00 PM | G23: Client lost | H23: 12:00-02:30 | I23: Client lost | J23: 02:30-04:30 | K23: Client lost | L23: 04:30-06:00 | M23: Client lost | O23: not interested. busy in studies | Q23: 14-5-2025
B24: 92 303 9578152 | C24: =COUNTIF(G24:M24, "Not attempted") -> 0 | D24: Not Attended | E24: Contacted | F24: 10:00 - 12:00 PM | G24: Not Recieved | H24: 12:00-02:30 | I24: Call Recieved | J24: 02:30-04:30 | K24: Not Recieved | L24: 04:30-06:00 | M24: Not Recieved | O24: awaiting response/ not reachable.cut the call immediately | Q24: 15-5-2025
B25: 92 304 2846019 | C25: =COUNTIF(G25:M25, "Not attempted") -> 0 | D25: Not Attended | E25: Closed - Lost | F25: 10:00 - 12:00 PM | G25: Client lost | H25: 12:00-02:30 | I25: Client lost | J25: 02:30-04:30 | K25: Client lost | L25: 04:30-06:00 | M25: Client lost | O25: he said internet problem | Q25: 15-5-2025
B26: 92 325 2899329 | C26: =COUNTIF(G26:M26, "Not attempted") -> 0 | D26: Call Attended | E26: Closed - Lost | F26: 10:00 - 12:00 PM | G26: Client lost | H26: 12:00-02:30 | I26: Client lost | J26: 02:30-04:30 | K26: Client lost | L26: 04:30-06:00 | M26: Client lost | O26: awaiting response/ not reachable. | Q26: 15-5-2025
B27: 92 342 4969217 | C27: =COUNTIF(G27:M27, "Not attempted") -> 0 | D27: Not Attended | E27: Closed - Lost | F27: 10:00 - 12:00 PM | G27: Client lost | H27: 12:00-02:30 | I27: Client lost | J27: 02:30-04:30 | K27: Client lost | L27: 04:30-06:00 | M27: Client lost | O27: not interested. | Q27: 15-5-2025
B28: 92 334 7879077 | C28: =COUNTIF(G28:M28, "Not attempted") -> 0 | D28: Call Attended | E28: Contacted | F28: 10:00 - 12:00 PM | G28: Call Recieved | H28: 12:00-02:30 | I28: Call Recieved | J28: 02:30-04:30 | K28: Not Recieved | L28: 04:30-06:00 | M28: Not Recieved | N28: qualified | O28: interested, will call him back at 6pm 17th may. call not receive. | Q28: 15-5-2025
B29: 92 307 0148989 | C29: =COUNTIF(G29:M29, "Not attempted") -> 0 | D29: Not Attended | E29: Closed - Lost | F29: 10:00 - 12:00 PM | G29: Client lost | H29: 12:00-02:30 | I29: Client lost | J29: 02:30-04:30 | K29: Client lost | L29: 04:30-06:00 | M29: Client lost | O29: physical classes | Q29: 15-5-2025
B30: 92 348 2900659 | C30: =COUNTIF(G30:M30, "Not attempted") -> 0 | D30: Call Attended | E30: Closed - Lost | F30: 10:00 - 12:00 PM | G30: Client lost | H30: 12:00-02:30 | I30: Client lost | J30: 02:30-04:30 | K30: Client lost | L30: 04:30-06:00 | M30: Client lost | O30: not interested in data science | Q30: 15-5-2025
B31: 92 313 2894151 | C31: =COUNTIF(G31:M31, "Not attempted") -> 1 | D31: Call Attended | E31: Awaiting Response | F31: 10:00 - 12:00 PM | G31: Call Recieved | H31: 12:00-02:30 | I31: Call Recieved | J31: 02:30-04:30 | K31: Not attempted | L31: 04:30-06:00 | M31: Not Recieved | O31: interested, will call him back at 5pm 19th may. not reachable | Q31: 15-5-2025
B32: 92 334 8668349 | C32: =COUNTIF(G32:M32, "Not attempted") -> 0 | D32: Call Attended | E32: Closed - Lost | F32: 10:00 - 12:00 PM | G32: Client lost | H32: 12:00-02:30 | I32: Client lost | J32: 02:30-04:30 | K32: Client lost | L32: 04:30-06:00 | M32: Client lost | N32: qualified | O32: She didn't get the permission. | Q32: 15-5-2025
B33: 92 315 5734149 | C33: =COUNTIF(G33:M33, "Not attempted") -> 0 | D33: Not Attended | E33: Contacted | F33: 10:00 - 12:00 PM | G33: Not Recieved | H33: 12:00-02:30 | I33: Call Recieved | J33: 02:30-04:30 | K33: Not Recieved | L33: 04:30-06:00 | M33: Not Recieved | O33: awaiting response/ not reachable. | Q33: 15-5-2025
B34: 92 315 4507252 | C34: =COUNTIF(G34:M34, "Not attempted") -> 0 | D34: Call Attended | E34: Closed - Lost | F34: 10:00 - 12:00 PM | G34: Client lost | H34: 12:00-02:30 | I34: Client lost | J34: 02:30-04:30 | K34: Client lost | L34: 04:30-06:00 | M34: Client lost | O34: not interested. | Q34: 15-5-2025
B35: 92 319 7682037 | C35: =COUNTIF(G35:M35, "Not attempted") -> 0 | D35: Call Attended | E35: Contacted | F35: 10:00 - 12:00 PM | G35: Not Recieved | H35: 12:00-02:30 | I35: Call Recieved | J35: 02:30-04:30 | K35: Not Recieved | L35: 04:30-06:00 | M35: Not Recieved | O35: She is filling out the form./ not reachable. | Q35: 15-5-2025
B36: 92 301 0909651 | C36: =COUNTIF(G36:M36, "Not attempted") -> 0 | D36: Call Attended | E36: Closed - Lost | F36: 10:00 - 12:00 PM | G36: Client lost | H36: 12:00-02:30 | I36: Client lost | J36: 02:30-04:30 | K36: Client lost | L36: 04:30-06:00 | M36: Client lost | O36: not interested, he is interested in onsite classes | Q36: 15-5-2025
B37: 92 318 1050520 | C37: =COUNTIF(G37:M37, "Not attempted") -> 1 | D37: Not Attended | E37: Awaiting payment | F37: 10:00 - 12:00 PM | G37: Call Recieved | H37: 12:00-02:30 | I37: Not Recieved | J37: 02:30-04:30 | K37: Not Recieved | L37: 04:30-06:00 | M37: Not attempted | O37: waiting for the payment / not reachable | Q37: 15-5-2025
B38: 92 313 2076659 | C38: =COUNTIF(G38:M38, "Not attempted") -> 0 | D38: Call Attended | E38: Awaiting Response | F38: 10:00 - 12:00 PM | G38: Not Recieved | H38: 12:00-02:30 | I38: Call Recieved | J38: 02:30-04:30 | K38: Call Recieved | L38: 04:30-06:00 | M38: Not Recieved | N38: qualified | O38: interested, she will come office. will call her back on 27 may. | Q38: 15-5-2025
B39: 92 348 8561743 | C39: =COUNTIF(G39:M39, "Not attempted") -> 0 | D39: Not Attended | E39: Call not Recieved | F39: 10:00 - 12:00 PM | G39: Not Recieved | H39: 12:00-02:30 | I39: Not Recieved | J39: 02:30-04:30 | K39: Not Recieved | L39: 04:30-06:00 | M39: Not Recieved | O39: no response | Q39: 15-5-2025
B40: 92 333 5758174 | C40: =COUNTIF(G40:M40, "Not attempted") -> 0 | D40: Call Attended | E40: Closed - Lost | F40: 10:00 - 12:00 PM | G40: Client lost | H40: 12:00-02:30 | I40: Client lost | J40: 02:30-04:30 | K40: Client lost | L40: 04:30-06:00 | M40: Client lost | N40: qualified | O40: not interested. | Q40: 15-5-2025
...

Sheet 3
A1: Prospect Name | B1: Number | C1: Attempts Missing | D1: Status | E1: stage | F1: Call Slot 1 | G1: Attempt 1 | H1: Call Slot 2 | I1: Attempt 2 | J1: Call Slot 3 | K1: Attempt-3 | L1: Call Slot 4 | M1: Attempt-4 | N1: Lead Type | O1: Notes | P1: Next Step | Q1: date
A2: Unknown | B2: 92 320 0666300 | D2: Call Attended | E2: demo | F2: 10:00 - 12:00 PM | G2: Not Recieved | H2: 12:00-02:30 | I2: Not Recieved | J2: 02:30-04:30 | K2: Call Recieved | L2: 04:30-06:00 | M2: Not attempted | N2: Pending | Q2: 45632
A3: Unknown | B3: 92 326 0822475 | D3: Call Attended | E3: Closed - Lost | F3: 10:00 - 12:00 PM | G3: Client lost | H3: 12:00-02:30 | I3: Client lost | J3: 02:30-04:30 | K3: Call Recieved | L3: 04:30-06:00 | M3: Client lost | N3: Pending | Q3: 45632
A4: Unknown | B4: 92 316 4133981 | D4: Call Attended | E4: Contacted | F4: 10:00 - 12:00 PM | G4: Not Recieved | H4: 12:00-02:30 | I4: Call Recieved | J4: 02:30-04:30 | K4: Not attempted | L4: 04:30-06:00 | M4: Not attempted | N4: Pending | Q4: 45632
A5: Unknown | B5: 92 333 5881325 | D5: Call Attended | E5: Contacted | F5: 10:00 - 12:00 PM | G5: Not attempted | H5: 12:00-02:30 | I5: Call Recieved | J5: 02:30-04:30 | K5: Not Recieved | L5: 04:30-06:00 | M5: Not attempted | N5: Pending | O5: call at 4:30 to 5:00 pm | Q5: 45632
